<?xml version='1.0'?>

<robot name="QCar" xmlns:xacro="http://www.ros.org/wiki/xacro">

  <xacro:include filename="$(find qcar_gazebo)/urdf/materials.xacro" />
  <xacro:include filename="$(find gazebo_ros_motors)/xacro/joint_motor.xacro"/>
  <xacro:include filename="$(find gazebo_ros_motors)/xacro/dc_motor.xacro"/> <!--dc motor plugin include--> 

  <!-- <xacro:include filename="$(find qcar_gazebo)/urdf/lidar.xacro" /> -->
  <xacro:include filename="$(find qcar_gazebo)/urdf/camera.xacro" />
  <xacro:include filename="$(find qcar_gazebo)/urdf/depth_camera.xacro" />
  <xacro:include filename="$(find qcar_gazebo)/urdf/imu.xacro" />


  <link name="base_footprint"/>

  <joint name="base_joint" type="fixed">
        <parent link="base_footprint"/>
        <child link="base"/>
  </joint>


  <link name="base">
        <visual>
            <origin rpy="0 0 0" xyz="0 0 0"/>
            <geometry>
                <mesh filename="package://qcar_gazebo/models/qcar/QCarBody.stl" scale="0.001 0.001 0.001"/>
            </geometry>
            <material name="white"/>
        </visual>
        <collision>
            <origin rpy="0 0 0" xyz="0 0 0"/>
            <geometry>
                <mesh filename="package://qcar_gazebo/models/qcar/QCarBody.stl" scale="0.001 0.001 0.001"/>
            </geometry>
        </collision>
        <inertial>
            <origin rpy="0 0 0" xyz="0 0 0"/>
            <mass value="0.1"/>
            <inertia ixx="0.001" ixy="0" ixz="0" iyy="0.001" iyz="0" izz="0.001"/>
        </inertial>
    </link>
    <joint name="body_lidar_joint" type="continuous">
        <parent link="base"/>
        <child link="lidar"/>
        <origin rpy="0 0 0" xyz="-0.01227 -0.00045 0.16152"/>
        <axis xyz="0 0 1"/>
    </joint>
    <link name="lidar">
        <visual>
            <origin rpy="0 0 0" xyz="0 0 0"/>
            <geometry>
                <mesh filename="package://qcar_gazebo/models/qcar/QCarLidar.stl" scale="0.001 0.001 0.001"/>
            </geometry>
            <material name="red"/>
        </visual>
        <collision>
            <origin rpy="0 0 0" xyz="0 0 0"/>
            <geometry>
                <mesh filename="package://qcar_gazebo/models/qcar/QCarLidar.stl" scale="0.001 0.001 0.001"/>
            </geometry>
        </collision>
        <inertial>
            <origin rpy="0 0 0" xyz="0 0 0"/>
            <mass value="0.1"/>
            <inertia ixx="0.001" ixy="0" ixz="0" iyy="0.001" iyz="0" izz="0.001"/>
        </inertial>
    </link>

    <joint name="base_hubfl_joint" type="revolute">
        <parent link="base"/>
        <child link="hubfl"/>
        <origin rpy="0 0 0" xyz="0.12960 0.05590 0.03338"/>
        <axis xyz="0 0 1"/>
        <dynamics damping="0.143" friction="0.0"/>
        <limit lower="-0.5236" upper="0.5236" effort="300" velocity="2"/>
        <!-- <limit lower="-3.1416" upper="3.1416" effort="300" velocity="2"/> -->
    </joint>
    <link name="hubfl">
        <visual>
            <origin rpy="0 0 0" xyz="0 0 0"/>
            <geometry>
                <mesh filename="package://qcar_gazebo/models/qcar/QCarSteeringHubL.stl" scale="0.001 0.001 0.001"/>
            </geometry>
            <material name="orange"/>
        </visual>
        <collision>
            <origin rpy="0 0 0" xyz="0 0 0"/>
            <geometry>
                <mesh filename="package://qcar_gazebo/models/qcar/QCarSteeringHubL.stl" scale="0.001 0.001 0.001"/>
            </geometry>
        </collision>
        <inertial>
            <origin rpy="0 0 0" xyz="0 0 0"/>
            <mass value="0.1"/>
            <inertia ixx="0.001" ixy="0" ixz="0" iyy="0.001" iyz="0" izz="0.001"/>
        </inertial>
    </link>
    <joint name="base_hubfr_joint" type="revolute">
        <parent link="base"/>
        <child link="hubfr"/>
        <origin rpy="0 0 0" xyz="0.12960 -0.05590 0.03338"/>
        <axis xyz="0 0 1"/>
        <limit lower="-0.5236" upper="0.5236" effort="300" velocity="2"/>
        <!-- <limit lower="-3.1416" upper="3.1416" effort="300" velocity="2"/> -->
        <dynamics damping="0.143" friction="0.0"/>
    </joint>
    <link name="hubfr">
        <visual>
            <origin rpy="0 0 0" xyz="0 0 0"/>
            <geometry>
                <mesh filename="package://qcar_gazebo/models/qcar/QCarSteeringHubR.stl" scale="0.001 0.001 0.001"/>
            </geometry>
            <material name="orange"/>
        </visual>
        <collision>
            <origin rpy="0 0 0" xyz="0 0 0"/>
            <geometry>
                <mesh filename="package://qcar_gazebo/models/qcar/QCarSteeringHubR.stl" scale="0.001 0.001 0.001"/>
            </geometry>
        </collision>
        <inertial>
            <origin rpy="0 0 0" xyz="0 0 0"/>
            <mass value="0.1"/>
            <inertia ixx="0.001" ixy="0" ixz="0" iyy="0.001" iyz="0" izz="0.001"/>
        </inertial>
    </link>
    <xacro:joint_motor motor_name="wheelfl_motor" parent_link="hubfl" child_link="wheelfl">
        <xacro:property name="params_yaml" value="$(find gazebo_ros_motors)/params/joint_motor.yaml"/>
        <origin xyz="0 0 0" rpy="0 0 3.14"/>
        <axis xyz="0 1 0" rpy="0 0 0"/>
    </xacro:joint_motor>
    <link name="wheelfl">
        <visual>
            <origin rpy="0 0 0" xyz="0 0 0"/>
            <geometry>
                <mesh filename="package://qcar_gazebo/models/qcar/QCarWheel.stl" scale="0.001 0.001 0.001"/>
            </geometry>
            <material name="red"/>
        </visual>
        <collision>
            <origin rpy="0 0 0" xyz="0 0 0"/>
            <geometry>
                <mesh filename="package://qcar_gazebo/models/qcar/QCarWheel.stl" scale="0.001 0.001 0.001"/>
            </geometry>
        </collision>
        <inertial>
            <origin rpy="0 0 0" xyz="0 0 0"/>
            <mass value="0.1"/>
            <inertia ixx="0.001" ixy="0" ixz="0" iyy="0.001" iyz="0" izz="0.001"/>
        </inertial>
    </link>
    <xacro:joint_motor motor_name="wheelfr_motor" parent_link="hubfr" child_link="wheelfr">
        <xacro:property name="params_yaml" value="$(find gazebo_ros_motors)/params/joint_motor.yaml"/>
        <origin xyz="0 0 0" rpy="0 0 0"/>
        <axis xyz="0 1 0" rpy="0 0 0"/>
    </xacro:joint_motor>
    <link name="wheelfr">
        <visual>
            <origin rpy="0 0 0" xyz="0 0 0"/>
            <geometry>
                <mesh filename="package://qcar_gazebo/models/qcar/QCarWheel.stl" scale="0.001 0.001 0.001"/>
            </geometry>
            <material name="orange"/>
        </visual>
        <collision>
            <origin rpy="0 0 0" xyz="0 0 0"/>
            <geometry>
                <mesh filename="package://qcar_gazebo/models/qcar/QCarWheel.stl" scale="0.001 0.001 0.001"/>
            </geometry>
        </collision>
        <inertial>
            <origin rpy="0 0 0" xyz="0 0 0"/>
            <mass value="0.1"/>
            <inertia ixx="0.001" ixy="0" ixz="0" iyy="0.001" iyz="0" izz="0.001"/>
        </inertial>
    </link>

    <xacro:joint_motor motor_name="wheelrl_motor" parent_link="base" child_link="wheelrl">
        <xacro:property name="params_yaml" value="$(find gazebo_ros_motors)/params/joint_motor.yaml"/>
        <origin xyz="-0.12765 0.05610 0.03338" rpy="0 0 3.14"/>
        <axis xyz="0 1 0" rpy="0 0 0"/>
    </xacro:joint_motor>
    <link name="wheelrl">
        <visual>
            <origin rpy="0 0 0" xyz="0 0 0"/>
            <geometry>
                <mesh filename="package://qcar_gazebo/models/qcar/QCarWheel.stl" scale="0.001 0.001 0.001"/>
            </geometry>
            <material name="orange"/>
        </visual>
        <collision>
            <origin rpy="0 0 0" xyz="0 0 0"/>
            <geometry>
                <mesh filename="package://qcar_gazebo/models/qcar/QCarWheel.stl" scale="0.001 0.001 0.001"/>
            </geometry>
        </collision>
        <inertial>
            <origin rpy="0 0 0" xyz="0 0 0"/>
            <mass value="0.1"/>
            <inertia ixx="0.001" ixy="0" ixz="0" iyy="0.001" iyz="0" izz="0.001"/>
        </inertial>
    </link>

    <xacro:joint_motor motor_name="wheelrr_motor" parent_link="base" child_link="wheelrr">
        <xacro:property name="params_yaml" value="$(find gazebo_ros_motors)/params/joint_motor.yaml"/>
        <origin xyz="-0.12765 -0.05610 0.03338" rpy="0 0 0"/>
        <axis xyz="0 1 0" rpy="0 0 0"/>
    </xacro:joint_motor>
    <link name="wheelrr">
        <visual>
            <origin rpy="0 0 0" xyz="0 0 0"/>    
            <geometry>
                <mesh filename="package://qcar_gazebo/models/qcar/QCarWheel.stl" scale="0.001 0.001 0.001"/>
            </geometry>
            <material name="red"/>
        </visual>
        <collision>
            <origin rpy="0 0 0" xyz="0 0 0"/>
            <geometry>
                <mesh filename="package://qcar_gazebo/models/qcar/QCarWheel.stl" scale="0.001 0.001 0.001"/>
            </geometry>
        </collision>
        <inertial>
            <origin rpy="0 0 0" xyz="0 0 0"/>
            <mass value="0.1"/>
            <inertia ixx="0.001" ixy="0" ixz="0" iyy="0.001" iyz="0" izz="0.001"/>
        </inertial>
    </link>

    <gazebo reference="wheelrl">
        <material>Gazebo/Black</material>
        <mu1 value="0.7"/>
        <mu2 value="0.7"/>
    </gazebo>

    <gazebo reference="wheelrr">
        <material>Gazebo/Black</material>
        <mu1 value="0.7"/>
        <mu2 value="0.7"/>
    </gazebo>

    <gazebo reference="wheelfl">
        <material>Gazebo/Black</material>
        <mu1 value="0.7"/>
        <mu2 value="0.7"/>
    </gazebo>

    <gazebo reference="wheelfr">
        <material>Gazebo/Black</material>
        <mu1 value="0.7"/>
        <mu2 value="0.7"/>
    </gazebo>

    <gazebo reference="lidar">
        <material>Gazebo/Blue</material>
    </gazebo>

    <joint name="camera_rgb_joint" type="fixed">
	    <!-- <axis xyz="0 1 0" /> -->
	    <!-- <origin xyz=".2 0 0" rpy="0 0 0"/> -->
        <origin rpy="0 0 0" xyz="0.081686 0 0.15445"/>
        <!-- <origin rpy="0 0 0" xyz="0 0 0"/> -->
	    <parent link="base"/>
	    <child link="camera_rgb"/>
  	</joint>
    <link name="camera_rgb"/>

    <joint name="camera_csi_front_joint" type="fixed">
        <!-- <axis xyz="0 1 0" /> -->
        <!-- <origin xyz=".2 0 0" rpy="0 0 0"/> -->
        <origin rpy="0 0 0" xyz="0.19236 -0.000475 0.093029"/>
        <!-- <origin rpy="0 0 0" xyz="0 0 0"/> -->
        <parent link="base"/>
        <child link="camera_csi_front"/>
    </joint>
    <link name="camera_csi_front"/>

    <joint name="camera_csi_right_joint" type="fixed">
        <!-- <axis xyz="0 1 0" /> -->
        <!-- <origin xyz=".2 0 0" rpy="0 0 0"/> -->
        <origin rpy="0 0 -1.5708" xyz="0.12887 -0.06755 0.093029"/>
        <!-- <origin rpy="0 0 0" xyz="0 0 0"/> -->
        <parent link="base"/>
        <child link="camera_csi_right"/>
    </joint>
    <link name="camera_csi_right"/>

    <joint name="camera_csi_back_joint" type="fixed">
        <!-- <axis xyz="0 1 0" /> -->
        <!-- <origin xyz=".2 0 0" rpy="0 0 0"/> -->
        <origin rpy="0 0 -3.1416" xyz="-0.16669 -0.000578 0.093029"/>
        <!-- <origin rpy="0 0 0" xyz="0 0 0"/> -->
        <parent link="base"/>
        <child link="camera_csi_back"/>
    </joint>
    <link name="camera_csi_back"/>

    <joint name="camera_csi_left_joint" type="fixed">
        <!-- <axis xyz="0 1 0" /> -->
        <!-- <origin xyz=".2 0 0" rpy="0 0 0"/> -->
        <origin rpy="0 0 1.5708" xyz="0.12784 0.052497 0.093029"/>
        <!-- <origin rpy="0 0 0" xyz="0 0 0"/> -->
        <parent link="base"/>
        <child link="camera_csi_left"/>
    </joint>
    <link name="camera_csi_left"/>

    <transmission name="body_lidar_tran">
        <type>>transmission_interface/SimpleTransmission</type>
        <joint name="body_lidar_joint">
            <hardwareInterface>hardware_interface/EffortJointInterface</hardwareInterface>
        </joint>
        <actuator name="body_lidar_motor">
            <mechanicalReduction>1</mechanicalReduction>
        </actuator>
    </transmission>

    <transmission name="base_hubfl_tran">
        <type>>transmission_interface/SimpleTransmission</type>
        <joint name="base_hubfl_joint">
            <hardwareInterface>hardware_interface/PositionJointInterface</hardwareInterface>
        </joint>
        <actuator name="base_hubfl_motor">
            <mechanicalReduction>1</mechanicalReduction>
        </actuator>
    </transmission>
    <transmission name="base_hubfr_tran">
        <type>>transmission_interface/SimpleTransmission</type>
        <joint name="base_hubfr_joint">
            <hardwareInterface>hardware_interface/PositionJointInterface</hardwareInterface>
        </joint>
        <actuator name="base_hubfr_motor">
            <mechanicalReduction>1</mechanicalReduction>
        </actuator>
    </transmission>

    <transmission name="hubfl_wheelfl_tran">
        <type>>transmission_interface/SimpleTransmission</type>
        <joint name="wheelfl_motor">
            <hardwareInterface>hardware_interface/EffortJointInterface</hardwareInterface>
        </joint>
        <actuator name="hubfl_wheelfl_motor">
            <mechanicalReduction>1</mechanicalReduction>
        </actuator>
    </transmission>
    <transmission name="hubfr_wheelfr_tran">
        <type>>transmission_interface/SimpleTransmission</type>
        <joint name="wheelfr_motor">
            <hardwareInterface>hardware_interface/EffortJointInterface</hardwareInterface>
        </joint>
        <actuator name="hubfr_wheelfr_motor">
            <mechanicalReduction>1</mechanicalReduction>
        </actuator>
    </transmission>

    <gazebo>
        <plugin name="gazebo_ros_control" filename="libgazebo_ros_control.so">
        <robotNamespace>/qcar</robotNamespace>
        </plugin>
    </gazebo>

    <gazebo>
        <plugin name="diff_drive" filename="libgazebo_ros_diff_drive.so">

            <leftJoint>wheelrl_motor</leftJoint>
            <rightJoint>wheelrr_motor</rightJoint>
            <wheel_separation>0.18</wheel_separation>
            <wheel_diameter>0.065</wheel_diameter>

           
            <max_wheel_torque>200</max_wheel_torque>
            <max_wheel_acceleration>10.0</max_wheel_acceleration>

            
         
            <odometry_frame>odom</odometry_frame>
            <robot_base_frame>base_footprint</robot_base_frame>

            <publish_odom>true</publish_odom>
            <publish_odom_tf>true</publish_odom_tf>
            <publish_wheel_tf>true</publish_wheel_tf>

        </plugin>
    </gazebo>

</robot>
  

